[35mDEBUG   [0m api_Test:test_normal.py:37 æ–­è¨€funcå‡½æ•°å¼‚å¸¸ç±»åž‹æ˜¯:<class 'ValueError'>